test1.csv
1,123456,50.00,7,ask
2,123457,5.00,15,bid
3,123458,49.00,74,ask
4,123459,53.00,70,ask
5,1234510,60.00,17,bid
6,1234511,50.00,457,ask
7,1234512,50.00,7678,ask
8,1234513,500.00,78,bid
1,123456,3.00,7,ask
2,123457,5000.00,15,bid
3,123458,49.00,74,ask
4,123459,467.00,70,ask
5,1234510,600.00,17,bid
6,1234511,50678.00,457,ask
7,1234512,5047.00,7678,ask
8,1234513,50047.00,78,bid
8,1234513,500471.00,78,bid
